Workbook

Sheet 日統計模板
A1: 累計客戶數(ALL) | B1: =DATEVALUE(RIGHT('DAY1'!$A4,5)) -> 45986 | D1: 淨客戶數(ALL) | E1: =B1 -> 45986
A2: 台北（第一服務中心） | B2: ='DAY1'!$I7 -> 103579 | D2: 台北（第一服務中心） | E2: ='DAY1'!$H7 -> -15
A3: 台北（第二服務中心） | B3: ='DAY1'!$I8 -> 55758 | D3: 台北（第二服務中心） | E3: ='DAY1'!$H8 -> -3
A4: 台北（第三服務中心） | B4: ='DAY1'!$I9 -> 48476 | D4: 台北（第三服務中心） | E4: ='DAY1'!$H9 -> 0
A5: 台北（第四服務中心） | B5: ='DAY1'!$I10 -> 62182 | D5: 台北（第四服務中心） | E5: ='DAY1'!$H10 -> -4
A6: 新北（第一服務中心） | B6: ='DAY1'!$I11 -> 150221 | D6: 新北（第一服務中心） | E6: ='DAY1'!$H11 -> -15
A7: 新北（第二服務中心） | B7: ='DAY1'!$I12 -> 107816 | D7: 新北（第二服務中心） | E7: ='DAY1'!$H12 -> 11
A8: 基隆 | B8: ='DAY1'!$I13 -> 64655 | D8: 基隆 | E8: ='DAY1'!$H13 -> -19
A9: 桃園 | B9: ='DAY1'!$I14 -> 196222 | D9: 桃園 | E9: ='DAY1'!$H14 -> -23
A10: 新竹 | B10: ='DAY1'!$I15 -> 105597 | D10: 新竹 | E10: ='DAY1'!$H15 -> 10
A11: 苗栗 | B11: ='DAY1'!$I16 -> 51808 | D11: 苗栗 | E11: ='DAY1'!$H16 -> -18
A12: 花蓮 | B12: ='DAY1'!$I17 -> 45536 | D12: 花蓮 | E12: ='DAY1'!$H17 -> -9
A13: 宜蘭 | B13: ='DAY1'!$I18 -> 32309 | D13: 宜蘭 | E13: ='DAY1'!$H18 -> 3
... A25: 全區 | B25: ='DAY1'!$I30 -> 2016473 | D25: 全區 | E25: ='DAY1'!$H30 -> -280
A28: 新裝申請數(ALL) | B28: =B1 -> 45986 | D28: 新裝待裝數 | E28: ALL
A29: 台北（第一服務中心） | B29: ='DAY1'!$D7 -> 13 | D29: 台北（第一服務中心） | E29: ='DAY1'!J7 -> 191
A30: 台北（第二服務中心） | B30: ='DAY1'!$D8 -> 15 | D30: 台北（第二服務中心） | E30: ='DAY1'!J8 -> 101
A31: 台北（第三服務中心） | B31: ='DAY1'!$D9 -> 9 | D31: 台北（第三服務中心） | E31: ='DAY1'!J9 -> 91
A32: 台北（第四服務中心） | B32: ='DAY1'!$D10 -> 16 | D32: 台北（第四服務中心） | E32: ='DAY1'!J10 -> 115
A33: 新北（第一服務中心） | B33: ='DAY1'!$D11 -> 30 | D33: 新北（第一服務中心） | E33: ='DAY1'!J11 -> 256
A34: 新北（第二服務中心） | B34: ='DAY1'!$D12 -> 23 | D34: 新北（第二服務中心） | E34: ='DAY1'!J12 -> 144
A35: 基隆 | B35: ='DAY1'!$D13 -> 5 | D35: 基隆 | E35: ='DAY1'!J13 -> 71
A36: 桃園 | B36: ='DAY1'!$D14 -> 57 | D36: 桃園 | E36: ='DAY1'!J14 -> 309
A37: 新竹 | B37: ='DAY1'!$D15 -> 17 | D37: 新竹 | E37: ='DAY1'!J15 -> 259
A38: 苗栗 | B38: ='DAY1'!$D16 -> 5 | D38: 苗栗 | E38: ='DAY1'!J16 -> 87
A39: 花蓮 | B39: ='DAY1'!$D17 -> 10 | D39: 花蓮 | E39: ='DAY1'!J17 -> 43
A40: 宜蘭 | B40: ='DAY1'!$D18 -> 7 | D40: 宜蘭 | E40: ='DAY1'!J18 -> 52
... A52: 全區 | B52: ='DAY1'!$D30 -> 422 | D52: 全區 | E52: ='DAY1'!J30 -> 3989
A55: 新裝竣工數(ALL) | B55: =B1 -> 45986
A56: 台北（第一服務中心） | B56: ='DAY1'!$E7 -> 19
A57: 台北（第二服務中心） | B57: ='DAY1'!$E8 -> 8
A58: 台北（第三服務中心） | B58: ='DAY1'!$E9 -> 17
A59: 台北（第四服務中心） | B59: ='DAY1'!$E10 -> 15
A60: 新北（第一服務中心） | B60: ='DAY1'!$E11 -> 29
A61: 新北（第二服務中心） | B61: ='DAY1'!$E12 -> 22
A62: 基隆 | B62: ='DAY1'!$E13 -> 10
A63: 桃園 | B63: ='DAY1'!$E14 -> 35
A64: 新竹 | B64: ='DAY1'!$E15 -> 24
A65: 苗栗 | B65: ='DAY1'!$E16 -> 5
A66: 花蓮 | B66: ='DAY1'!$E17 -> 10
...

Sheet 無上網日統計模板
A1: 累計客戶數(ALL) | B1: =日統計模板!B1 -> 45986
A2: 台北（第一服務中心） | B2: ='DAY1'!$H64 -> 8058
A3: 台北（第二服務中心） | B3: ='DAY1'!$H65 -> 2745
A4: 台北（第三服務中心） | B4: ='DAY1'!$H66 -> 3685
A5: 台北（第四服務中心） | B5: ='DAY1'!$H67 -> 4909
A6: 新北（第一服務中心） | B6: ='DAY1'!$H68 -> 12699
A7: 新北（第二服務中心） | B7: ='DAY1'!$H69 -> 7132
A8: 基隆 | B8: ='DAY1'!$H70 -> 8353
A9: 桃園 | B9: ='DAY1'!$H71 -> 21524
A10: 新竹 | B10: ='DAY1'!$H72 -> 15044
A11: 苗栗 | B11: ='DAY1'!$H73 -> 7466
A12: 花蓮 | B12: ='DAY1'!$H74 -> 12461
A13: 宜蘭 | B13: ='DAY1'!$H75 -> 6325
A14: 北區 | B14: =SUM(B2:B13) -> 110401
A15: 臺中 | B15: ='DAY1'!$H76 -> 30680
A16: 彰化 | B16: ='DAY1'!$H77 -> 6928
A17: 南投 | B17: ='DAY1'!$H78 -> 9119
A18: 雲林 | B18: ='DAY1'!$H79 -> 6817
A19: 嘉義 | B19: ='DAY1'!$H80 -> 10941
A20: 台南 | B20: ='DAY1'!$H81 -> 26822
A21: 高雄 | B21: ='DAY1'!$H82 -> 32211
A22: 屏東 | B22: ='DAY1'!$H83 -> 15502
A23: 台東 | B23: ='DAY1'!$H84 -> 7628
A24: 南區 | B24: =SUM(B15:B23) -> 146648
A25: 全區 | B25: =B14+B24 -> 257049
A28: 新裝申請數(ALL) | B28: =B1 -> 45986
A29: 台北（第一服務中心） | B29: ='DAY1'!$D64 -> 0
A30: 台北（第二服務中心） | B30: ='DAY1'!$D65 -> 0
A31: 台北（第三服務中心） | B31: ='DAY1'!$D66 -> 2
A32: 台北（第四服務中心） | B32: ='DAY1'!$D67 -> 0
A33: 新北（第一服務中心） | B33: ='DAY1'!$D68 -> 1
A34: 新北（第二服務中心） | B34: ='DAY1'!$D69 -> 3
A35: 基隆 | B35: ='DAY1'!$D70 -> 0
A36: 桃園 | B36: ='DAY1'!$D71 -> 2
A37: 新竹 | B37: ='DAY1'!$D72 -> 1
A38: 苗栗 | B38: ='DAY1'!$D73 -> 1
A39: 花蓮 | B39: ='DAY1'!$D74 -> 2
A40: 宜蘭 | B40: ='DAY1'!$D75 -> 0
A41: 北區 | B41: =SUM(B29:B40) -> 12
A42: 臺中 | B42: ='DAY1'!$D76 -> 7
...

Sheet DAY1
A4: 統計日期: 2025/11/25
A5: 統計條件: 事業群:全部
A6: 序號 | B6: 營運處 | C6: 大服 | D6: 申請數 | E6: 竣工數 | F6: 註銷數 | G6: 退租數 | H6: 客戶數 | I6: 總客戶數 | J6: 待裝數 | K6: 退租申請數
A7: 1 | B7: 台北 | C7: 一服 | D7: 13 | E7: 19 | F7: 2 | G7: 32 | H7: -15 | I7: 103579 | J7: 191 | K7: 23
A8: 1 | B8: 台北 | C8: 二服 | D8: 15 | E8: 8 | F8: 0 | G8: 13 | H8: -3 | I8: 55758 | J8: 101 | K8: 17
A9: 1 | B9: 台北 | C9: 三服 | D9: 9 | E9: 17 | F9: 2 | G9: 17 | H9: 0 | I9: 48476 | J9: 91 | K9: 26
A10: 1 | B10: 台北 | C10: 四服 | D10: 16 | E10: 15 | F10: 1 | G10: 17 | H10: -4 | I10: 62182 | J10: 115 | K10: 12
A11: 2 | B11: 新北 | C11: 一服 | D11: 30 | E11: 29 | F11: 8 | G11: 40 | H11: -15 | I11: 150221 | J11: 256 | K11: 46
A12: 2 | B12: 新北 | C12: 二服 | D12: 23 | E12: 22 | F12: 7 | G12: 12 | H12: 11 | I12: 107816 | J12: 144 | K12: 34
A13: 3 | B13: 基隆 | D13: 5 | E13: 10 | F13: 3 | G13: 29 | H13: -19 | I13: 64655 | J13: 71 | K13: 18
A14: 4 | B14: 桃園 | D14: 57 | E14: 35 | F14: 9 | G14: 52 | H14: -23 | I14: 196222 | J14: 309 | K14: 81
A15: 5 | B15: 新竹 | D15: 17 | E15: 24 | F15: 0 | G15: 15 | H15: 10 | I15: 105597 | J15: 259 | K15: 28
A16: 6 | B16: 苗栗 | D16: 5 | E16: 5 | F16: 1 | G16: 23 | H16: -18 | I16: 51808 | J16: 87 | K16: 14
A17: 7 | B17: 花蓮 | D17: 10 | E17: 10 | F17: 1 | G17: 19 | H17: -9 | I17: 45536 | J17: 43 | K17: 8
A18: 8 | B18: 宜蘭 | D18: 7 | E18: 9 | F18: 0 | G18: 6 | H18: 3 | I18: 32309 | J18: 52 | K18: 5
B19: 北區 | D19: 207 | E19: 203 | F19: 34 | G19: 275 | H19: -82 | I19: 1024159 | J19: 1719 | K19: 312
A20: 10 | B20: 臺中 | D20: 46 | E20: 51 | F20: 1 | G20: 71 | H20: -20 | I20: 252178 | J20: 428 | K20: 55
A21: 11 | B21: 彰化 | D21: 17 | E21: 14 | F21: 2 | G21: 18 | H21: -6 | I21: 85777 | J21: 177 | K21: 24
A22: 12 | B22: 南投 | D22: 9 | E22: 13 | F22: 1 | G22: 11 | H22: 0 | I22: 47696 | J22: 124 | K22: 11
A23: 13 | B23: 雲林 | D23: 20 | E23: 11 | F23: 3 | G23: 11 | H23: -1 | I23: 56358 | J23: 144 | K23: 12
A24: 14 | B24: 嘉義 | D24: 22 | E24: 11 | F24: 2 | G24: 66 | H24: -55 | I24: 71968 | J24: 160 | K24: 12
A25: 15 | B25: 台南 | D25: 44 | E25: 22 | F25: 4 | G25: 59 | H25: -38 | I25: 177763 | J25: 442 | K25: 43
A26: 16 | B26: 高雄 | D26: 44 | E26: 32 | F26: 0 | G26: 82 | H26: -49 | I26: 220239 | J26: 566 | K26: 51
A27: 17 | B27: 屏東 | D27: 7 | E27: 2 | F27: 0 | G27: 22 | H27: -19 | I27: 57550 | J27: 143 | K27: 23
A28: 18 | B28: 台東 | D28: 6 | E28: 0 | F28: 0 | G28: 10 | H28: -10 | I28: 22785 | J28: 86 | K28: 10
B29: 南區 | D29: 215 | E29: 156 | F29: 13 | G29: 350 | H29: -198 | I29: 992314 | J29: 2270 | K29: 241
B30: 總計 | D30: 422 | E30: 359 | F30: 47 | G30: 625 | H30: -280 | I30: 2016473 | J30: 3989 | K30: 553
A33: 統計日期: 2025/11/25
A34: 統計條件: 事業群:全部
A35: 序號 | B35: 營運處 | C35: 服務 | D35: 2機 | E35: 3機 | F35: 4機
A36: 1 | B36: 台北 | C36: 一服 | D36: 8958 | E36: 1663 | F36: 585
A37: 1 | B37: 台北 | C37: 二服 | D37: 4145 | E37: 755 | F37: 230
A38: 1 | B38: 台北 | C38: 三服 | D38: 3190 | E38: 607 | F38: 218
A39: 1 | B39: 台北 | C39: 四服 | D39: 4678 | E39: 782 | F39: 235
A40: 2 | B40: 新北 | C40: 一服 | D40: 13022 | E40: 2113 | F40: 655
A41: 2 | B41: 新北 | C41: 二服 | D41: 8962 | E41: 1625 | F41: 495
A42: 3 | B42: 基隆 | D42: 7783 | E42: 1214 | F42: 352
A43: 4 | B43: 桃園 | D43: 25929 | E43: 4593 | F43: 1496
A44: 5 | B44: 新竹 | D44: 17216 | E44: 2400 | F44: 702
A45: 6 | B45: 苗栗 | D45: 8943 | E45: 1679 | F45: 575
...
